[{"text": ["\"ImportError: No module named dummy\" on fresh Django project"], "childNum": 0, "tag": "h2", "senID": 0, "childList": []}, {"text": ["I've got the following installed through MacPorts on MacOS X 10.5.6:"], "childNum": 0, "tag": "p", "senID": 1, "childList": []}, {"code": "<pre>\n<code>\n py25-sqlite3 @2.5.4_0 (active)\npython25 @2.5.4_1+darwin_9+macosx (active)\nsqlite3 @3.6.12_0 (active)\n</code>\n</pre>\n", "senID": 2}, {"text": ["python25 is correctly set as my system's default Python."], "childNum": 1, "tag": "p", "senID": 3, "childList": [{"text": "python25", "childNum": 0, "tag": "code", "pos": 0, "childList": []}]}, {"text": ["I downloaded a fresh copy of Django 1.1 beta (I have the same problem with 1.0 and trunk, though) and installed it with \"sudo python setup.py install\"."], "childNum": 1, "tag": "p", "senID": 4, "childList": [{"text": "sudo python setup.py install", "childNum": 0, "tag": "code", "pos": 0, "childList": []}]}, {"text": ["Things seem to load correctly through the interactive interpreter:"], "childNum": 0, "tag": "p", "senID": 5, "childList": []}, {"code": "<pre>\n<code>\n $ python\nPython 2.5.4 (r254:67916, Apr 10 2009, 16:02:52) \n[GCC 4.0.1 (Apple Inc. build 5490)] on darwin\nType \"help\", \"copyright\", \"credits\" or \"license\" for more information.\n&gt;&gt;&gt; import django\n&gt;&gt;&gt; import sqlite3\n&gt;&gt;&gt; ^D\n</code>\n</pre>\n", "senID": 6}, {"text": ["But:"], "childNum": 0, "tag": "p", "senID": 7, "childList": []}, {"code": "<pre>\n<code>\n $ django-admin.py startproject foo\n$ cd foo/\n$ python manage.py runserver\nValidating models...\nUnhandled exception in thread started by &lt;function inner_run at 0x6c1e70&gt;\nTraceback (most recent call last):\n  File \"/opt/local/Library/Frameworks/Python.framework/Versions/2.5/lib/python2.5/site-packages/django/core/management/commands/runserver.py\", line 48, in inner_run\n    self.validate(display_num_errors=True)\n  File \"/opt/local/Library/Frameworks/Python.framework/Versions/2.5/lib/python2.5/site-packages/django/core/management/base.py\", line 246, in validate\n    num_errors = get_validation_errors(s, app)\n  File \"/opt/local/Library/Frameworks/Python.framework/Versions/2.5/lib/python2.5/site-packages/django/core/management/validation.py\", line 22, in get_validation_errors\n    from django.db import models, connection\n  File \"/opt/local/Library/Frameworks/Python.framework/Versions/2.5/lib/python2.5/site-packages/django/db/__init__.py\", line 22, in &lt;module&gt;\n    backend = __import__('%s.base' % settings.DATABASE_ENGINE, {}, {}, [''])\nImportError: No module named dummy.base\n</code>\n</pre>\n", "senID": 8}, {"text": ["If I change DATABASE_ENGINE in settings.py to \"sqlite3\", I get the following, seemingly related problem:"], "childNum": 3, "tag": "p", "senID": 9, "childList": [{"text": "DATABASE_ENGINE", "childNum": 0, "tag": "code", "pos": 0, "childList": []}, {"text": "settings.py", "childNum": 0, "tag": "code", "childList": []}, {"text": "sqlite3", "childNum": 0, "tag": "code", "childList": []}]}, {"code": "<pre>\n<code>\n $ python manage.py runserver\n\nValidating models...\nUnhandled exception in thread started by &lt;function inner_run at 0x6c1e70&gt;\nTraceback (most recent call last):\n  File \"/opt/local/Library/Frameworks/Python.framework/Versions/2.5/lib/python2.5/site-packages/django/core/management/commands/runserver.py\", line 48, in inner_run\n    self.validate(display_num_errors=True)\n  File \"/opt/local/Library/Frameworks/Python.framework/Versions/2.5/lib/python2.5/site-packages/django/core/management/base.py\", line 246, in validate\n    num_errors = get_validation_errors(s, app)\n  File \"/opt/local/Library/Frameworks/Python.framework/Versions/2.5/lib/python2.5/site-packages/django/core/management/validation.py\", line 22, in get_validation_errors\n    from django.db import models, connection\n  File \"/opt/local/Library/Frameworks/Python.framework/Versions/2.5/lib/python2.5/site-packages/django/db/__init__.py\", line 22, in &lt;module&gt;\n    backend = __import__('%s.base' % settings.DATABASE_ENGINE, {}, {}, [''])\nImportError: No module named base\n^C$\n</code>\n</pre>\n", "senID": 10}, {"text": ["I swear this all worked a few days ago and I don't recall changing anything related to Django or Python, installation-wise."], "childNum": 0, "tag": "p", "senID": 11, "childList": []}, {"text": ["My various Google adventures have turned up nothing useful.", "So... Any ideas?"], "childNum": 0, "tag": "p", "senID": 12, "childList": []}, {"text": ["Edit: 'syncdb' raises the same exceptions."], "childNum": 1, "tag": "p", "senID": 13, "childList": [{"text": "syncdb", "childNum": 0, "tag": "code", "pos": 0, "childList": []}]}]